<?xml version="1.0" encoding="utf-8"?>
<robot name="dual_xarm6">
  <link name="world" />
  <link name="L_base_anchor" />
  <joint name="L_base_anchor_to_world" type="fixed">
    <parent link="world" />
    <child link="L_base_anchor" />
    <origin rpy="0 0 0" xyz="0 0 0" />
  </joint>
  <material name="L_Black">
    <color rgba="0.0 0.0 0.0 1.0" />
  </material>
  <material name="L_Red">
    <color rgba="0.8 0.0 0.0 1.0" />
  </material>
  <material name="L_White">
    <color rgba="1.0 1.0 1.0 1.0" />
  </material>
  <material name="L_Silver">
    <color rgba="0.753 0.753 0.753 1.0" />
  </material>
  <joint name="L_world_joint" type="fixed">
    <parent link="L_base_anchor" />
    <child link="L_link_base" />
    <origin rpy="0 0 0" xyz="0 0 0" />
  </joint>
  <link name="L_link_base">
    <inertial>
      <origin rpy="0 0 0" xyz="0.0 0.0 0.09103" />
      <mass value="2.7" />
      <inertia ixx="0.00494875" ixy="-3.5E-06" ixz="1.25E-05" iyy="0.00494174" iyz="1.67E-06" izz="0.002219" />
    </inertial>
    <visual>
      <geometry>
        <mesh filename="meshes/link_base.stl" />
      </geometry>
      <origin rpy="0 0 0" xyz="0 0 0" />
      <material name="L_White" />
    </visual>
    <collision name="sphere_0">
      <origin xyz="0.0 0.0 0.06437774599471613" rpy="0 0 0" />
      <geometry>
        <sphere radius="0.05623931699330031" />
      </geometry>
    </collision>
    <collision name="sphere_1">
      <origin xyz="0.0 0.0 0.12014432095522473" rpy="0 0 0" />
      <geometry>
        <sphere radius="0.06041831946211072" />
      </geometry>
    </collision>
  </link>
  <link name="L_link1">
    <inertial>
      <origin rpy="0 0 0" xyz="0.00022 0.02951 -0.0124" />
      <mass value="2.3814" />
      <inertia ixx="0.0058562" ixy="-1.79e-05" ixz="3.55e-06" iyy="0.0050316" iyz="-0.000888336" izz="0.003536652" />
    </inertial>
    <visual>
      <geometry>
        <mesh filename="meshes/link1.stl" />
      </geometry>
      <origin rpy="0 0 0" xyz="0 0 0" />
      <material name="L_White" />
    </visual>
    <collision name="sphere_2">
      <origin xyz="0.0 9.739381825451225e-06 -0.07692728339928506" rpy="0 0 0" />
      <geometry>
        <sphere radius="0.06142438468845244" />
      </geometry>
    </collision>
    <collision name="sphere_3">
      <origin xyz="0.0 -0.005002474423637519 -0.009213942523522811" rpy="0 0 0" />
      <geometry>
        <sphere radius="0.06188658573835742" />
      </geometry>
    </collision>
    <collision name="sphere_4">
      <origin xyz="0.0 0.046724347896974536 0.0" rpy="0 0 0" />
      <geometry>
        <sphere radius="0.055" />
      </geometry>
    </collision>
  </link>
  <joint name="L_joint1" type="revolute">
    <parent link="L_link_base" />
    <child link="L_link1" />
    <origin rpy="0 0 0" xyz="0 0 0.267" />
    <axis xyz="0 0 1" />
    <limit effort="50.0" lower="-6.283185307179586" upper="6.283185307179586" velocity="3.14" />
    <dynamics damping="1.0" friction="1.0" />
  </joint>
  <link name="L_link2">
    <inertial>
      <origin rpy="0 0 0" xyz="0.03881 -0.22783 0.03496" />
      <mass value="2.2675" />
      <inertia ixx="0.028315776" ixy="0.005" ixz="0.00066546" iyy="0.0058" iyz="-0.0045741" izz="0.0273447" />
    </inertial>
    <visual>
      <geometry>
        <mesh filename="meshes/link2.stl" />
      </geometry>
      <origin rpy="0 0 0" xyz="0 0 0" />
      <material name="L_White" />
    </visual>
    <collision name="sphere_5">
      <origin xyz="0.0039746029802274485 -1.1102230246251565e-16 0.08972958044536905" rpy="0 0 0" />
      <geometry>
        <sphere radius="0.053144640769369575" />
      </geometry>
    </collision>
    <collision name="sphere_6">
      <origin xyz="-4.701977403289151e-38 -0.10363209352511488 0.07620007826066691" rpy="0 0 0" />
      <geometry>
        <sphere radius="0.055856447627448555" />
      </geometry>
    </collision>
    <collision name="sphere_7">
      <origin xyz="-4.701977403289151e-38 -0.043606162030582984 0.08449853391621046" rpy="0 0 0" />
      <geometry>
        <sphere radius="0.0544142135623731" />
      </geometry>
    </collision>
    <collision name="sphere_8">
      <origin xyz="-0.0005554985742835374 -0.10869429954675502 0.012660786017956598" rpy="0 0 0" />
      <geometry>
        <sphere radius="0.06059684199718284" />
      </geometry>
    </collision>
    <collision name="sphere_9">
      <origin xyz="0.0010882236699592124 -0.17455645090517202 4.235164736271502e-22" rpy="0 0 0" />
      <geometry>
        <sphere radius="0.05836395147692988" />
      </geometry>
    </collision>
    <collision name="sphere_10">
      <origin xyz="0.007483004204308766 -0.2606192733768142 -0.016046405072493403" rpy="0 0 0" />
      <geometry>
        <sphere radius="0.06742045832918686" />
      </geometry>
    </collision>
    <collision name="sphere_11">
      <origin xyz="0.058928754455178894 -0.30049201427159095 -0.02030411175422858" rpy="0 0 0" />
      <geometry>
        <sphere radius="0.058683804594407155" />
      </geometry>
    </collision>
    <collision name="sphere_12">
      <origin xyz="0.05676984934555941 -0.2993629604849997 0.04652822551987668" rpy="0 0 0" />
      <geometry>
        <sphere radius="0.061099010563439735" />
      </geometry>
    </collision>
  </link>
  <joint name="L_joint2" type="revolute">
    <parent link="L_link1" />
    <child link="L_link2" />
    <origin rpy="-1.5708 0 0" xyz="0 0 0" />
    <axis xyz="0 0 1" />
    <limit effort="50.0" lower="-2.059" upper="2.0944" velocity="3.14" />
    <dynamics damping="1.0" friction="1.0" />
  </joint>
  <link name="L_link3">
    <inertial>
      <origin rpy="0 0 0" xyz="0.07041 0.11631 0.0107" />
      <mass value="1.875" />
      <inertia ixx="0.0063483" ixy="-0.0015397" ixz="0.00096858" iyy="0.00379758" iyz="0.00186567" izz="0.00595768" />
    </inertial>
    <visual>
      <geometry>
        <mesh filename="meshes/link3.stl" />
      </geometry>
      <origin rpy="0 0 0" xyz="0 0 0" />
      <material name="L_White" />
    </visual>
    <collision name="sphere_13">
      <origin xyz="0.003913205608467696 5.551115123125783e-17 0.06762921076093321" rpy="0 0 0" />
      <geometry>
        <sphere radius="0.05" />
      </geometry>
    </collision>
    <collision name="sphere_14">
      <origin xyz="0.06912608579525814 0.08233515019282062 0.07078882994785993" rpy="0 0 0" />
      <geometry>
        <sphere radius="0.05700232380083802" />
      </geometry>
    </collision>
    <collision name="sphere_15">
      <origin xyz="0.08329201776310557 0.0812582307149175 0.004730867370335855" rpy="0 0 0" />
      <geometry>
        <sphere radius="0.05527781097761699" />
      </geometry>
    </collision>
    <collision name="sphere_16">
      <origin xyz="0.07887599861589589 0.13699438027830263 -1.9058241313221758e-21" rpy="0 0 0" />
      <geometry>
        <sphere radius="0.05308665964460359" />
      </geometry>
    </collision>
    <collision name="sphere_17">
      <origin xyz="0.029938184173170956 0.02858709519809649 0.0857446350873164" rpy="0 0 0" />
      <geometry>
        <sphere radius="0.049" />
      </geometry>
    </collision>
  </link>
  <joint name="L_joint3" type="revolute">
    <parent link="L_link2" />
    <child link="L_link3" />
    <origin rpy="0 0 0" xyz="0.0535 -0.2845 0" />
    <axis xyz="0 0 1" />
    <limit effort="32.0" lower="-3.927" upper="0.19198" velocity="3.14" />
    <dynamics damping="1.0" friction="1.0" />
  </joint>
  <link name="L_link4">
    <inertial>
      <origin rpy="0 0 0" xyz="-0.00018 0.01798 -0.02291" />
      <mass value="1.3192" />
      <inertia ixx="0.004896" ixy="-6.925e-06" ixz="-1.418e-05" iyy="0.00445694" iyz="-0.00023186" izz="0.00134332" />
    </inertial>
    <visual>
      <geometry>
        <mesh filename="meshes/link4.stl" />
      </geometry>
      <origin rpy="0 0 0" xyz="0 0 0" />
      <material name="L_White" />
    </visual>
    <collision name="sphere_18">
      <origin xyz="0.0 0.012750462118971531 4.440892098500626e-16" rpy="0 0 0" />
      <geometry>
        <sphere radius="0.04307572505442989" />
      </geometry>
    </collision>
    <collision name="sphere_19">
      <origin xyz="0.0 0.05523979788811918 -0.005157837570566648" rpy="0 0 0" />
      <geometry>
        <sphere radius="0.048" />
      </geometry>
    </collision>
    <collision name="sphere_20">
      <origin xyz="2.220446049250313e-16 0.007110765590532614 -0.1522814157132643" rpy="0 0 0" />
      <geometry>
        <sphere radius="0.05" />
      </geometry>
    </collision>
    <collision name="sphere_21">
      <origin xyz="0.014877772221562835 0.05931410311447845 -0.08036412697886874" rpy="0 0 0" />
      <geometry>
        <sphere radius="0.04841421356237319" />
      </geometry>
    </collision>
  </link>
  <joint name="L_joint4" type="revolute">
    <parent link="L_link3" />
    <child link="L_link4" />
    <origin rpy="-1.5708 0 0" xyz="0.0775 0.3425 0" />
    <axis xyz="0 0 1" />
    <limit effort="32.0" lower="-6.283185307179586" upper="6.283185307179586" velocity="3.14" />
    <dynamics damping="1.0" friction="1.0" />
  </joint>
  <link name="L_link5">
    <inertial>
      <origin rpy="0 0 0" xyz="0.0651 0.03096 0.00315" />
      <mass value="1.33854" />
      <inertia ixx="0.00146378" ixy="-0.000450624" ixz="0.000284306" iyy="0.00184192" iyz="0.000130866" izz="0.002333524" />
    </inertial>
    <visual>
      <geometry>
        <mesh filename="meshes/link5.stl" />
      </geometry>
      <origin rpy="0 0 0" xyz="0 0 0" />
      <material name="L_White" />
    </visual>
    <collision name="sphere_22">
      <origin xyz="-8.881784197001252e-16 -0.0008895930857889534 0.02095903966676521" rpy="0 0 0" />
      <geometry>
        <sphere radius="0.046" />
      </geometry>
    </collision>
    <collision name="sphere_23">
      <origin xyz="0.07179619208954191 -2.220446049250313e-16 0.00278842089479317" rpy="0 0 0" />
      <geometry>
        <sphere radius="0.051414213562372836" />
      </geometry>
    </collision>
    <collision name="sphere_24">
      <origin xyz="0.07389238809294574 0.06474502320945186 1.6653345369377348e-16" rpy="0 0 0" />
      <geometry>
        <sphere radius="0.05" />
      </geometry>
    </collision>
  </link>
  <joint name="L_joint5" type="revolute">
    <parent link="L_link4" />
    <child link="L_link5" />
    <origin rpy="1.5708 0 0" xyz="0 0 0" />
    <axis xyz="0 0 1" />
    <limit effort="32.0" lower="-1.69297" upper="3.141592653589793" velocity="3.14" />
    <dynamics damping="1.0" friction="1.0" />
  </joint>
  <link name="L_link6">
    <inertial>
      <origin rpy="0 0 0" xyz="0 -0.00677 -0.01098" />
      <mass value="0.17" />
      <inertia ixx="9.3e-05" ixy="-0.0" ixz="-0.0" iyy="5.87e-05" iyz="-3.6e-06" izz="0.000132" />
    </inertial>
    <visual>
      <geometry>
        <mesh filename="meshes/link6.stl" />
      </geometry>
      <origin rpy="0 0 0" xyz="0 0 0" />
      <material name="L_Silver" />
    </visual>
  </link>
  <joint name="L_joint6" type="revolute">
    <parent link="L_link5" />
    <child link="L_link6" />
    <origin rpy="-1.5708 0 0" xyz="0.076 0.097 0" />
    <axis xyz="0 0 1" />
    <limit effort="20.0" lower="-6.283185307179586" upper="6.283185307179586" velocity="3.14" />
    <dynamics damping="1.0" friction="1.0" />
  </joint>
  <transmission name="L_tran1">
    <type>transmission_interface/SimpleTransmission</type>
    <joint name="L_joint1">
      <hardwareInterface>hardware_interface/PositionJointInterface</hardwareInterface>
    </joint>
    <actuator name="L_motor1">
      <hardwareInterface>hardware_interface/PositionJointInterface</hardwareInterface>
      <mechanicalReduction>100</mechanicalReduction>
    </actuator>
  </transmission>
  <transmission name="L_tran2">
    <type>transmission_interface/SimpleTransmission</type>
    <joint name="L_joint2">
      <hardwareInterface>hardware_interface/PositionJointInterface</hardwareInterface>
    </joint>
    <actuator name="L_motor2">
      <hardwareInterface>hardware_interface/PositionJointInterface</hardwareInterface>
      <mechanicalReduction>100</mechanicalReduction>
    </actuator>
  </transmission>
  <transmission name="L_tran3">
    <type>transmission_interface/SimpleTransmission</type>
    <joint name="L_joint3">
      <hardwareInterface>hardware_interface/PositionJointInterface</hardwareInterface>
    </joint>
    <actuator name="L_motor3">
      <hardwareInterface>hardware_interface/PositionJointInterface</hardwareInterface>
      <mechanicalReduction>100</mechanicalReduction>
    </actuator>
  </transmission>
  <transmission name="L_tran4">
    <type>transmission_interface/SimpleTransmission</type>
    <joint name="L_joint4">
      <hardwareInterface>hardware_interface/PositionJointInterface</hardwareInterface>
    </joint>
    <actuator name="L_motor4">
      <hardwareInterface>hardware_interface/PositionJointInterface</hardwareInterface>
      <mechanicalReduction>100</mechanicalReduction>
    </actuator>
  </transmission>
  <transmission name="L_tran5">
    <type>transmission_interface/SimpleTransmission</type>
    <joint name="L_joint5">
      <hardwareInterface>hardware_interface/PositionJointInterface</hardwareInterface>
    </joint>
    <actuator name="L_motor5">
      <hardwareInterface>hardware_interface/PositionJointInterface</hardwareInterface>
      <mechanicalReduction>100</mechanicalReduction>
    </actuator>
  </transmission>
  <transmission name="L_tran6">
    <type>transmission_interface/SimpleTransmission</type>
    <joint name="L_joint6">
      <hardwareInterface>hardware_interface/PositionJointInterface</hardwareInterface>
    </joint>
    <actuator name="L_motor6">
      <hardwareInterface>hardware_interface/PositionJointInterface</hardwareInterface>
      <mechanicalReduction>100</mechanicalReduction>
    </actuator>
  </transmission>
  <gazebo reference="L_link_base">
    <selfCollide>true</selfCollide>
  </gazebo>
  <gazebo reference="L_link1">
    <selfCollide>true</selfCollide>
  </gazebo>
  <gazebo reference="L_link2">
    <selfCollide>true</selfCollide>
  </gazebo>
  <gazebo reference="L_link3">
    <selfCollide>true</selfCollide>
  </gazebo>
  <gazebo reference="L_link4">
    <selfCollide>true</selfCollide>
  </gazebo>
  <gazebo reference="L_link5">
    <selfCollide>true</selfCollide>
  </gazebo>
  <gazebo reference="L_link6">
    <selfCollide>true</selfCollide>
  </gazebo>
  <link name="L_link_eef">
    <visual>
      <geometry>
        <mesh filename="meshes/d435_with_cam_stand.stl" />
      </geometry>
      <origin rpy="0 0 0" xyz="0 0 0" />
      <material name="L_Silver" />
    </visual>
    <collision name="sphere_25">
      <origin xyz="0.06279373469039284 0.023649147603013954 0.015162320295711074" rpy="0 0 0" />
      <geometry>
        <sphere radius="0.02641421356237308" />
      </geometry>
    </collision>
    <collision name="sphere_26">
      <origin xyz="0.061867744815430115 -0.022684149323510372 0.014836797482413067" rpy="0 0 0" />
      <geometry>
        <sphere radius="0.025414213562373177" />
      </geometry>
    </collision>
  </link>
  <link name="L_camera_link" />
  <link name="L_camera_depth_frame" />
  <link name="L_camera_depth_optical_frame" />
  <link name="L_camera_color_frame" />
  <link name="L_camera_color_optical_frame" />
  <link name="L_camera_left_ir_frame" />
  <link name="L_camera_left_ir_optical_frame" />
  <link name="L_camera_right_ir_frame" />
  <link name="L_camera_right_ir_optical_frame" />
  <joint name="L_camera_link_joint" type="fixed">
    <parent link="L_link_eef" />
    <child link="L_camera_link" />
    <origin rpy="3.141592653589793 -1.5707963267948966 0" xyz="0.06746 -0.0175 0.0237" />
  </joint>
  <joint name="L_camera_depth_joint" type="fixed">
    <parent link="L_camera_link" />
    <child link="L_camera_depth_frame" />
    <origin rpy="0 0 0" xyz="0 0 0" />
  </joint>
  <joint name="L_camera_depth_optical_joint" type="fixed">
    <parent link="L_camera_depth_frame" />
    <child link="L_camera_depth_optical_frame" />
    <origin rpy="-1.5707963267948966 0 -1.5707963267948966" xyz="0 0 0" />
  </joint>
  <joint name="L_camera_color_joint" type="fixed">
    <parent link="L_camera_link" />
    <child link="L_camera_color_frame" />
    <origin rpy="0 0 0" xyz="0 0.015 0" />
  </joint>
  <joint name="L_camera_color_optical_joint" type="fixed">
    <parent link="L_camera_color_frame" />
    <child link="L_camera_color_optical_frame" />
    <origin rpy="-1.5707963267948966 0 -1.5707963267948966" xyz="0 0 0" />
  </joint>
  <joint name="L_camera_left_ir_joint" type="fixed">
    <parent link="L_camera_link" />
    <child link="L_camera_left_ir_frame" />
    <origin rpy="0 0 0" xyz="0 0 0" />
  </joint>
  <joint name="L_camera_left_ir_optical_joint" type="fixed">
    <parent link="L_camera_left_ir_frame" />
    <child link="L_camera_left_ir_optical_frame" />
    <origin rpy="-1.5707963267948966 0 -1.5707963267948966" xyz="0 0 0" />
  </joint>
  <joint name="L_camera_right_ir_joint" type="fixed">
    <parent link="L_camera_link" />
    <child link="L_camera_right_ir_frame" />
    <origin rpy="0 0 0" xyz="0 -0.050 0" />
  </joint>
  <joint name="L_camera_right_ir_optical_joint" type="fixed">
    <parent link="L_camera_right_ir_frame" />
    <child link="L_camera_right_ir_optical_frame" />
    <origin rpy="-1.5707963267948966 0 -1.5707963267948966" xyz="0 0 0" />
  </joint>
  <gazebo reference="L_camera_depth_frame">
    <sensor name="L_cameradepth" type="depth">
      <camera name="L_camera">
        <horizontal_fov>1.57</horizontal_fov>
        <image>
          <width>1280</width>
          <height>720</height>
        </image>
        <clip>
          <near>0.1</near>
          <far>100</far>
        </clip>
        <noise>
          <type>gaussian</type>
          <mean>0.0</mean>
          <stddev>0.100</stddev>
        </noise>
      </camera>
      <always_on>1</always_on>
      <update_rate>30</update_rate>
      <visualize>0</visualize>
    </sensor>
  </gazebo>
  <gazebo reference="L_camera_color_frame">
    <sensor name="L_cameracolor" type="camera">
      <camera name="L_camera">
        <horizontal_fov>1.57</horizontal_fov>
        <image>
          <width>1280</width>
          <height>720</height>
          <format>RGB_INT8</format>
        </image>
        <clip>
          <near>0.1</near>
          <far>100</far>
        </clip>
        <noise>
          <type>gaussian</type>
          <mean>0.0</mean>
          <stddev>0.007</stddev>
        </noise>
      </camera>
      <always_on>1</always_on>
      <update_rate>30</update_rate>
      <visualize>1</visualize>
    </sensor>
  </gazebo>
  <gazebo reference="L_camera_left_ir_frame">
    <sensor name="L_cameraired1" type="camera">
      <camera name="L_camera">
        <horizontal_fov>1.57</horizontal_fov>
        <image>
          <width>1280</width>
          <height>720</height>
          <format>L_INT8</format>
        </image>
        <clip>
          <near>0.1</near>
          <far>100</far>
        </clip>
        <noise>
          <type>gaussian</type>
          <mean>0.0</mean>
          <stddev>0.05</stddev>
        </noise>
      </camera>
      <always_on>1</always_on>
      <update_rate>30</update_rate>
      <visualize>0</visualize>
    </sensor>
  </gazebo>
  <gazebo reference="L_camera_right_ir_frame">
    <sensor name="L_cameraired2" type="camera">
      <camera name="L_camera">
        <horizontal_fov>1.57</horizontal_fov>
        <image>
          <width>1280</width>
          <height>720</height>
          <format>L_INT8</format>
        </image>
        <clip>
          <near>0.1</near>
          <far>100</far>
        </clip>
        <noise>
          <type>gaussian</type>
          <mean>0.0</mean>
          <stddev>0.05</stddev>
        </noise>
      </camera>
      <always_on>1</always_on>
      <update_rate>30</update_rate>
      <visualize>0</visualize>
    </sensor>
  </gazebo>
  <gazebo>
    <plugin filename="librealsense_gazebo_plugin.so" name="realsense_gazebo_camera">
      <prefix>L_camera</prefix>
      <depthUpdateRate>30.0</depthUpdateRate>
      <colorUpdateRate>30.0</colorUpdateRate>
      <infraredUpdateRate>30.0</infraredUpdateRate>
      <depthTopicName>L_aligned_depth_to_color/image_raw</depthTopicName>
      <depthCameraInfoTopicName>L_depth/camera_info</depthCameraInfoTopicName>
      <colorTopicName>L_color/image_raw</colorTopicName>
      <colorCameraInfoTopicName>L_color/camera_info</colorCameraInfoTopicName>
      <infrared1TopicName>L_infra1/image_raw</infrared1TopicName>
      <infrared1CameraInfoTopicName>L_infra1/camera_info</infrared1CameraInfoTopicName>
      <infrared2TopicName>L_infra2/image_raw</infrared2TopicName>
      <infrared2CameraInfoTopicName>L_infra2/camera_info</infrared2CameraInfoTopicName>
      <colorOpticalframeName>L_camera_color_optical_frame</colorOpticalframeName>
      <depthOpticalframeName>L_camera_depth_optical_frame</depthOpticalframeName>
      <infrared1OpticalframeName>L_camera_left_ir_optical_frame</infrared1OpticalframeName>
      <infrared2OpticalframeName>L_camera_right_ir_optical_frame</infrared2OpticalframeName>
      <rangeMinDepth>0.3</rangeMinDepth>
      <rangeMaxDepth>3.0</rangeMaxDepth>
      <pointCloud>true</pointCloud>
      <pointCloudTopicName>L_depth/color/points</pointCloudTopicName>
      <pointCloudCutoff>0.3</pointCloudCutoff>
    </plugin>
  </gazebo>
  <joint name="L_joint_eef" type="fixed">
    <origin rpy="0 0 0" xyz="0 0 0" />
    <parent link="L_link6" />
    <child link="L_link_eef" />
  </joint>
  <joint name="L_gripper_fix" type="fixed">
    <parent link="L_link_eef" />
    <child link="L_xarm_gripper_base_link" />
    <origin rpy="0 0 0" xyz="0 0 0" />
  </joint>
  <link name="L_xarm_gripper_base_link">
    <inertial>
      <origin rpy="0 0 0" xyz="-0.00065489 -0.0018497 0.048028" />
      <mass value="0.54156" />
      <inertia ixx="0.00047106" ixy="3.9292E-07" ixz="2.6537E-06" iyy="0.00033072" iyz="-1.0975E-05" izz="0.00025642" />
    </inertial>
    <visual>
      <geometry>
        <mesh filename="meshes/base_link.stl" />
      </geometry>
      <origin rpy="0 0 0" xyz="0 0 0" />
      <material name="L_White" />
    </visual>
    <collision name="sphere_27">
      <origin xyz="0.0 0.021408598442209437 0.038569046798902606" rpy="0 0 0" />
      <geometry>
        <sphere radius="0.045" />
      </geometry>
    </collision>
    <collision name="sphere_28">
      <origin xyz="0.0 -0.027208259023810577 0.02974245065168324" rpy="0 0 0" />
      <geometry>
        <sphere radius="0.045" />
      </geometry>
    </collision>
    <collision name="sphere_29">
      <origin xyz="-1.1102230246251565e-16 0.0444656172722705 0.08318401484654281" rpy="0 0 0" />
      <geometry>
        <sphere radius="0.044" />
      </geometry>
    </collision>
    <collision name="sphere_30">
      <origin xyz="-1.1102230246251565e-16 -0.05169408008738835 0.08041762764194593" rpy="0 0 0" />
      <geometry>
        <sphere radius="0.044" />
      </geometry>
    </collision>
    <collision name="sphere_31">
      <origin xyz="-1.1102230246251565e-16 -1.6653345369377348e-16 0.06765859485327008" rpy="0 0 0" />
      <geometry>
        <sphere radius="0.044" />
      </geometry>
    </collision>
  </link>
  <link name="L_left_outer_knuckle">
    <inertial>
      <origin rpy="0 0 0" xyz="2.9948E-14 0.021559 0.015181" />
      <mass value="0.033618" />
      <inertia ixx="1.9111E-05" ixy="-1.8803E-17" ixz="-1.1002E-17" iyy="6.6256E-06" iyz="-7.3008E-06" izz="1.3185E-05" />
    </inertial>
    <visual>
      <geometry>
        <mesh filename="meshes/left_outer_knuckle.stl" />
      </geometry>
      <origin rpy="0 0 0" xyz="0 0 0" />
      <material name="L_Silver" />
    </visual>
  </link>
  <joint name="L_drive_joint" type="revolute">
    <origin rpy="0 0 0" xyz="0 0.035 0.059098" />
    <parent link="L_xarm_gripper_base_link" />
    <child link="L_left_outer_knuckle" />
    <axis xyz="1 0 0" />
    <limit effort="50" lower="0" upper="0.85" velocity="2" />
  </joint>
  <link name="L_left_finger">
    <inertial>
      <origin rpy="0 0 0" xyz="-2.4536E-14 -0.016413 0.029258" />
      <mass value="0.048304" />
      <inertia ixx="1.7493E-05" ixy="-4.2156E-19" ixz="6.9164E-18" iyy="1.7225E-05" iyz="4.6433E-06" izz="5.1466E-06" />
    </inertial>
    <visual>
      <geometry>
        <mesh filename="meshes/left_finger.stl" />
      </geometry>
      <origin rpy="0 0 0" xyz="0 0 0" />
      <material name="L_Silver" />
    </visual>
    <collision name="sphere_32">
      <origin xyz="-1.2212453270876722e-15 -0.015735800096064345 0.048885242158388076" rpy="0 0 0" />
      <geometry>
        <sphere radius="0.019" />
      </geometry>
    </collision>
    <collision name="sphere_33">
      <origin xyz="0.0 -0.015374925454853472 0.03324483777039544" rpy="0 0 0" />
      <geometry>
        <sphere radius="0.019" />
      </geometry>
    </collision>
  </link>
  <joint name="L_left_finger_joint" type="revolute">
    <origin rpy="0 0 0" xyz="0 0.035465 0.042039" />
    <parent link="L_left_outer_knuckle" />
    <child link="L_left_finger" />
    <axis xyz="-1 0 0" />
    <limit effort="50" lower="0" upper="0.85" velocity="2" />
    <mimic joint="L_drive_joint" multiplier="1" offset="0" />
  </joint>
  <link name="L_left_inner_knuckle">
    <inertial>
      <origin rpy="0 0 0" xyz="1.86600784687907E-06 0.0220467847633621 0.0261334672830885" />
      <mass value="0.0230125781256706" />
      <inertia ixx="6.09490024271906E-06" ixy="6.06651326160071E-11" ixz="7.19102670500635E-11" iyy="6.01955084375188E-06" iyz="-2.75316812991721E-06" izz="5.07862004479903E-06" />
    </inertial>
    <visual>
      <geometry>
        <mesh filename="meshes/left_inner_knuckle.stl" />
      </geometry>
      <origin rpy="0 0 0" xyz="0 0 0" />
      <material name="L_Silver" />
    </visual>
  </link>
  <joint name="L_left_inner_knuckle_joint" type="revolute">
    <origin rpy="0 0 0" xyz="0 0.02 0.074098" />
    <parent link="L_xarm_gripper_base_link" />
    <child link="L_left_inner_knuckle" />
    <axis xyz="1 0 0" />
    <limit effort="50" lower="0" upper="0.85" velocity="2" />
    <mimic joint="L_drive_joint" multiplier="1" offset="0" />
  </joint>
  <link name="L_right_outer_knuckle">
    <inertial>
      <origin rpy="0 0 0" xyz="-3.1669E-14 -0.021559 0.015181" />
      <mass value="0.033618" />
      <inertia ixx="1.9111E-05" ixy="-1.8789E-17" ixz="1.0986E-17" iyy="6.6256E-06" iyz="7.3008E-06" izz="1.3185E-05" />
    </inertial>
    <visual>
      <geometry>
        <mesh filename="meshes/right_outer_knuckle.stl" />
      </geometry>
      <origin rpy="0 0 0" xyz="0 0 0" />
      <material name="L_Silver" />
    </visual>
  </link>
  <joint name="L_right_outer_knuckle_joint" type="revolute">
    <origin rpy="0 0 0" xyz="0 -0.035 0.059098" />
    <parent link="L_xarm_gripper_base_link" />
    <child link="L_right_outer_knuckle" />
    <axis xyz="-1 0 0" />
    <limit effort="50" lower="0" upper="0.85" velocity="2" />
    <mimic joint="L_drive_joint" multiplier="1" offset="0" />
  </joint>
  <link name="L_right_finger">
    <inertial>
      <origin rpy="0 0 0" xyz="2.5618E-14 0.016413 0.029258" />
      <mass value="0.048304" />
      <inertia ixx="1.7493E-05" ixy="-5.0014E-19" ixz="-7.5079E-18" iyy="1.7225E-05" iyz="-4.6435E-06" izz="5.1466E-06" />
    </inertial>
    <visual>
      <geometry>
        <mesh filename="meshes/right_finger.stl" />
      </geometry>
      <origin rpy="0 0 0" xyz="0 0 0" />
      <material name="L_Silver" />
    </visual>
    <collision name="sphere_34">
      <origin xyz="-4.440892098500626e-16 0.013904890286745408 0.04785105103424969" rpy="0 0 0" />
      <geometry>
        <sphere radius="0.019" />
      </geometry>
    </collision>
    <collision name="sphere_35">
      <origin xyz="-3.3306690738754696e-16 0.013608832539368731 0.0326232671765182" rpy="0 0 0" />
      <geometry>
        <sphere radius="0.019" />
      </geometry>
    </collision>
  </link>
  <joint name="L_right_finger_joint" type="revolute">
    <origin rpy="0 0 0" xyz="0 -0.035465 0.042039" />
    <parent link="L_right_outer_knuckle" />
    <child link="L_right_finger" />
    <axis xyz="1 0 0" />
    <limit effort="50" lower="0" upper="0.85" velocity="2" />
    <mimic joint="L_drive_joint" multiplier="1" offset="0" />
  </joint>
  <link name="L_right_inner_knuckle">
    <inertial>
      <origin rpy="0 0 0" xyz="1.866E-06 -0.022047 0.026133" />
      <mass value="0.023013" />
      <inertia ixx="6.0949E-06" ixy="-6.0665E-11" ixz="7.191E-11" iyy="6.0197E-06" iyz="2.7531E-06" izz="5.0784E-06" />
    </inertial>
    <visual>
      <geometry>
        <mesh filename="meshes/right_inner_knuckle.stl" />
      </geometry>
      <origin rpy="0 0 0" xyz="0 0 0" />
      <material name="L_Silver" />
    </visual>
  </link>
  <joint name="L_right_inner_knuckle_joint" type="revolute">
    <origin rpy="0 0 0" xyz="0 -0.02 0.074098" />
    <parent link="L_xarm_gripper_base_link" />
    <child link="L_right_inner_knuckle" />
    <axis xyz="-1 0 0" />
    <limit effort="50" lower="0" upper="0.85" velocity="2" />
    <mimic joint="L_drive_joint" multiplier="1" offset="0" />
  </joint>
  <link name="L_link_tcp" />
  <joint name="L_joint_tcp" type="fixed">
    <origin rpy="0 0 0" xyz="0 0 0.172" />
    <parent link="L_xarm_gripper_base_link" />
    <child link="L_link_tcp" />
  </joint>
  <transmission name="L_drive_joint_trans">
    <type>transmission_interface/SimpleTransmission</type>
    <joint name="L_drive_joint">
      <hardwareInterface>hardware_interface/PositionJointInterface</hardwareInterface>
    </joint>
    <actuator name="L_drive_joint_motor">
      <hardwareInterface>hardware_interface/PositionJointInterface</hardwareInterface>
      <mechanicalReduction>1</mechanicalReduction>
    </actuator>
  </transmission>
  <gazebo reference="L_xarm_gripper_base_link">
    <selfCollide>false</selfCollide>
  </gazebo>
  <gazebo reference="L_left_outer_knuckle">
    <selfCollide>false</selfCollide>
  </gazebo>
  <gazebo reference="L_left_finger">
    <selfCollide>false</selfCollide>
  </gazebo>
  <gazebo reference="L_left_inner_knuckle">
    <selfCollide>false</selfCollide>
  </gazebo>
  <gazebo reference="L_right_outer_knuckle">
    <selfCollide>false</selfCollide>
  </gazebo>
  <gazebo reference="L_right_finger">
    <selfCollide>false</selfCollide>
  </gazebo>
  <gazebo reference="L_right_inner_knuckle">
    <selfCollide>false</selfCollide>
  </gazebo>
  <gazebo>
    <plugin filename="libgazebo_grasp_fix.so" name="gazebo_grasp_fix">
      <arm>
        <arm_name>xarm_gripper</arm_name>
        <palm_link>L_link6</palm_link>
        <gripper_link>L_left_inner_knuckle</gripper_link>
        <gripper_link>L_right_inner_knuckle</gripper_link>
        <gripper_link>L_left_finger</gripper_link>
        <gripper_link>L_right_finger</gripper_link>
      </arm>
      <forces_angle_tolerance>100</forces_angle_tolerance>
      <update_rate>10</update_rate>
      <grip_count_threshold>2</grip_count_threshold>
      <max_grip_count>3</max_grip_count>
      <release_tolerance>0.0198</release_tolerance>
      <disable_collisions_on_attach>false</disable_collisions_on_attach>
      <contact_topic>__default_topic__</contact_topic>
    </plugin>
  </gazebo>
  <gazebo>
    <plugin filename="libroboticsgroup_gazebo_mimic_joint_plugin.so" name="L_left_finger_jointmimic_joint_plugin">
      <joint>L_drive_joint</joint>
      <mimicJoint>L_left_finger_joint</mimicJoint>
      <multiplier>1.0</multiplier>
      <offset>0</offset>
      <sensitiveness>0.0</sensitiveness>
      <maxEffort>10.0</maxEffort>
    </plugin>
  </gazebo>
  <gazebo>
    <plugin filename="libroboticsgroup_gazebo_mimic_joint_plugin.so" name="L_left_inner_knuckle_jointmimic_joint_plugin">
      <joint>L_drive_joint</joint>
      <mimicJoint>L_left_inner_knuckle_joint</mimicJoint>
      <multiplier>1.0</multiplier>
      <offset>0</offset>
      <sensitiveness>0.0</sensitiveness>
      <maxEffort>10.0</maxEffort>
    </plugin>
  </gazebo>
  <gazebo>
    <plugin filename="libroboticsgroup_gazebo_mimic_joint_plugin.so" name="L_right_outer_knuckle_jointmimic_joint_plugin">
      <joint>L_drive_joint</joint>
      <mimicJoint>L_right_outer_knuckle_joint</mimicJoint>
      <multiplier>1.0</multiplier>
      <offset>0</offset>
      <sensitiveness>0.0</sensitiveness>
      <maxEffort>10.0</maxEffort>
    </plugin>
  </gazebo>
  <gazebo>
    <plugin filename="libroboticsgroup_gazebo_mimic_joint_plugin.so" name="L_right_finger_jointmimic_joint_plugin">
      <joint>L_drive_joint</joint>
      <mimicJoint>L_right_finger_joint</mimicJoint>
      <multiplier>1.0</multiplier>
      <offset>0</offset>
      <sensitiveness>0.0</sensitiveness>
      <maxEffort>10.0</maxEffort>
    </plugin>
  </gazebo>
  <gazebo>
    <plugin filename="libroboticsgroup_gazebo_mimic_joint_plugin.so" name="L_right_inner_knuckle_jointmimic_joint_plugin">
      <joint>L_drive_joint</joint>
      <mimicJoint>L_right_inner_knuckle_joint</mimicJoint>
      <multiplier>1.0</multiplier>
      <offset>0</offset>
      <sensitiveness>0.0</sensitiveness>
      <maxEffort>10.0</maxEffort>
    </plugin>
  </gazebo>
  <link name="L_camera_calib_link" />
  <joint name="L_camera_calib_mount" type="fixed">
    <parent link="L_link6" />
    <child link="L_camera_calib_link" />
    <origin rpy="-0.004565 -0.002717 -1.549195" xyz="0.030576 0.068701 -0.016253" />
  </joint>
  <link name="R_base_anchor" />
  <joint name="R_base_anchor_to_world" type="fixed">
    <parent link="world" />
    <child link="R_base_anchor" />
    <origin rpy="0 0 0" xyz="0 -0.72 0" />
  </joint>
  <material name="R_Black">
    <color rgba="0.0 0.0 0.0 1.0" />
  </material>
  <material name="R_Red">
    <color rgba="0.8 0.0 0.0 1.0" />
  </material>
  <material name="R_White">
    <color rgba="1.0 1.0 1.0 1.0" />
  </material>
  <material name="R_Silver">
    <color rgba="0.753 0.753 0.753 1.0" />
  </material>
  <joint name="R_world_joint" type="fixed">
    <parent link="R_base_anchor" />
    <child link="R_link_base" />
    <origin rpy="0 0 0" xyz="0 0 0" />
  </joint>
  <link name="R_link_base">
    <inertial>
      <origin rpy="0 0 0" xyz="0.0 0.0 0.09103" />
      <mass value="2.7" />
      <inertia ixx="0.00494875" ixy="-3.5E-06" ixz="1.25E-05" iyy="0.00494174" iyz="1.67E-06" izz="0.002219" />
    </inertial>
    <visual>
      <geometry>
        <mesh filename="meshes/link_base.stl" />
      </geometry>
      <origin rpy="0 0 0" xyz="0 0 0" />
      <material name="R_White" />
    </visual>
    <collision name="sphere_36">
      <origin xyz="0.0 0.0 0.06437774599471613" rpy="0 0 0" />
      <geometry>
        <sphere radius="0.05623931699330031" />
      </geometry>
    </collision>
    <collision name="sphere_37">
      <origin xyz="0.0 0.0 0.12014432095522473" rpy="0 0 0" />
      <geometry>
        <sphere radius="0.06041831946211072" />
      </geometry>
    </collision>
  </link>
  <link name="R_link1">
    <inertial>
      <origin rpy="0 0 0" xyz="0.00022 0.02951 -0.0124" />
      <mass value="2.3814" />
      <inertia ixx="0.0058562" ixy="-1.79e-05" ixz="3.55e-06" iyy="0.0050316" iyz="-0.000888336" izz="0.003536652" />
    </inertial>
    <visual>
      <geometry>
        <mesh filename="meshes/link1.stl" />
      </geometry>
      <origin rpy="0 0 0" xyz="0 0 0" />
      <material name="R_White" />
    </visual>
    <collision name="sphere_38">
      <origin xyz="0.0 9.739381825451225e-06 -0.07692728339928506" rpy="0 0 0" />
      <geometry>
        <sphere radius="0.06142438468845244" />
      </geometry>
    </collision>
    <collision name="sphere_39">
      <origin xyz="0.0 -0.005002474423637519 -0.009213942523522811" rpy="0 0 0" />
      <geometry>
        <sphere radius="0.06188658573835742" />
      </geometry>
    </collision>
    <collision name="sphere_40">
      <origin xyz="0.0 0.046724347896974536 0.0" rpy="0 0 0" />
      <geometry>
        <sphere radius="0.055" />
      </geometry>
    </collision>
  </link>
  <joint name="R_joint1" type="revolute">
    <parent link="R_link_base" />
    <child link="R_link1" />
    <origin rpy="0 0 0" xyz="0 0 0.267" />
    <axis xyz="0 0 1" />
    <limit effort="50.0" lower="-6.283185307179586" upper="6.283185307179586" velocity="3.14" />
    <dynamics damping="1.0" friction="1.0" />
  </joint>
  <link name="R_link2">
    <inertial>
      <origin rpy="0 0 0" xyz="0.03881 -0.22783 0.03496" />
      <mass value="2.2675" />
      <inertia ixx="0.028315776" ixy="0.005" ixz="0.00066546" iyy="0.0058" iyz="-0.0045741" izz="0.0273447" />
    </inertial>
    <visual>
      <geometry>
        <mesh filename="meshes/link2.stl" />
      </geometry>
      <origin rpy="0 0 0" xyz="0 0 0" />
      <material name="R_White" />
    </visual>
    <collision name="sphere_41">
      <origin xyz="0.0039746029802274485 -1.1102230246251565e-16 0.08972958044536905" rpy="0 0 0" />
      <geometry>
        <sphere radius="0.053144640769369575" />
      </geometry>
    </collision>
    <collision name="sphere_42">
      <origin xyz="-4.701977403289151e-38 -0.10363209352511488 0.07620007826066691" rpy="0 0 0" />
      <geometry>
        <sphere radius="0.055856447627448555" />
      </geometry>
    </collision>
    <collision name="sphere_43">
      <origin xyz="-4.701977403289151e-38 -0.043606162030582984 0.08449853391621046" rpy="0 0 0" />
      <geometry>
        <sphere radius="0.0544142135623731" />
      </geometry>
    </collision>
    <collision name="sphere_44">
      <origin xyz="-0.0005554985742835374 -0.10869429954675502 0.012660786017956598" rpy="0 0 0" />
      <geometry>
        <sphere radius="0.06059684199718284" />
      </geometry>
    </collision>
    <collision name="sphere_45">
      <origin xyz="0.0010882236699592124 -0.17455645090517202 4.235164736271502e-22" rpy="0 0 0" />
      <geometry>
        <sphere radius="0.05836395147692988" />
      </geometry>
    </collision>
    <collision name="sphere_46">
      <origin xyz="0.007483004204308766 -0.2606192733768142 -0.016046405072493403" rpy="0 0 0" />
      <geometry>
        <sphere radius="0.06742045832918686" />
      </geometry>
    </collision>
    <collision name="sphere_47">
      <origin xyz="0.058928754455178894 -0.30049201427159095 -0.02030411175422858" rpy="0 0 0" />
      <geometry>
        <sphere radius="0.058683804594407155" />
      </geometry>
    </collision>
    <collision name="sphere_48">
      <origin xyz="0.05676984934555941 -0.2993629604849997 0.04652822551987668" rpy="0 0 0" />
      <geometry>
        <sphere radius="0.061099010563439735" />
      </geometry>
    </collision>
  </link>
  <joint name="R_joint2" type="revolute">
    <parent link="R_link1" />
    <child link="R_link2" />
    <origin rpy="-1.5708 0 0" xyz="0 0 0" />
    <axis xyz="0 0 1" />
    <limit effort="50.0" lower="-2.059" upper="2.0944" velocity="3.14" />
    <dynamics damping="1.0" friction="1.0" />
  </joint>
  <link name="R_link3">
    <inertial>
      <origin rpy="0 0 0" xyz="0.07041 0.11631 0.0107" />
      <mass value="1.875" />
      <inertia ixx="0.0063483" ixy="-0.0015397" ixz="0.00096858" iyy="0.00379758" iyz="0.00186567" izz="0.00595768" />
    </inertial>
    <visual>
      <geometry>
        <mesh filename="meshes/link3.stl" />
      </geometry>
      <origin rpy="0 0 0" xyz="0 0 0" />
      <material name="R_White" />
    </visual>
    <collision name="sphere_49">
      <origin xyz="0.003913205608467696 5.551115123125783e-17 0.06762921076093321" rpy="0 0 0" />
      <geometry>
        <sphere radius="0.05" />
      </geometry>
    </collision>
    <collision name="sphere_50">
      <origin xyz="0.06912608579525814 0.08233515019282062 0.07078882994785993" rpy="0 0 0" />
      <geometry>
        <sphere radius="0.05700232380083802" />
      </geometry>
    </collision>
    <collision name="sphere_51">
      <origin xyz="0.08329201776310557 0.0812582307149175 0.004730867370335855" rpy="0 0 0" />
      <geometry>
        <sphere radius="0.05527781097761699" />
      </geometry>
    </collision>
    <collision name="sphere_52">
      <origin xyz="0.07887599861589589 0.13699438027830263 -1.9058241313221758e-21" rpy="0 0 0" />
      <geometry>
        <sphere radius="0.05308665964460359" />
      </geometry>
    </collision>
    <collision name="sphere_53">
      <origin xyz="0.029938184173170956 0.02858709519809649 0.0857446350873164" rpy="0 0 0" />
      <geometry>
        <sphere radius="0.049" />
      </geometry>
    </collision>
  </link>
  <joint name="R_joint3" type="revolute">
    <parent link="R_link2" />
    <child link="R_link3" />
    <origin rpy="0 0 0" xyz="0.0535 -0.2845 0" />
    <axis xyz="0 0 1" />
    <limit effort="32.0" lower="-3.927" upper="0.19198" velocity="3.14" />
    <dynamics damping="1.0" friction="1.0" />
  </joint>
  <link name="R_link4">
    <inertial>
      <origin rpy="0 0 0" xyz="-0.00018 0.01798 -0.02291" />
      <mass value="1.3192" />
      <inertia ixx="0.004896" ixy="-6.925e-06" ixz="-1.418e-05" iyy="0.00445694" iyz="-0.00023186" izz="0.00134332" />
    </inertial>
    <visual>
      <geometry>
        <mesh filename="meshes/link4.stl" />
      </geometry>
      <origin rpy="0 0 0" xyz="0 0 0" />
      <material name="R_White" />
    </visual>
    <collision name="sphere_54">
      <origin xyz="0.0 0.012750462118971531 4.440892098500626e-16" rpy="0 0 0" />
      <geometry>
        <sphere radius="0.04307572505442989" />
      </geometry>
    </collision>
    <collision name="sphere_55">
      <origin xyz="0.0 0.05523979788811918 -0.005157837570566648" rpy="0 0 0" />
      <geometry>
        <sphere radius="0.048" />
      </geometry>
    </collision>
    <collision name="sphere_56">
      <origin xyz="2.220446049250313e-16 0.007110765590532614 -0.1522814157132643" rpy="0 0 0" />
      <geometry>
        <sphere radius="0.05" />
      </geometry>
    </collision>
    <collision name="sphere_57">
      <origin xyz="0.014877772221562835 0.05931410311447845 -0.08036412697886874" rpy="0 0 0" />
      <geometry>
        <sphere radius="0.04841421356237319" />
      </geometry>
    </collision>
  </link>
  <joint name="R_joint4" type="revolute">
    <parent link="R_link3" />
    <child link="R_link4" />
    <origin rpy="-1.5708 0 0" xyz="0.0775 0.3425 0" />
    <axis xyz="0 0 1" />
    <limit effort="32.0" lower="-6.283185307179586" upper="6.283185307179586" velocity="3.14" />
    <dynamics damping="1.0" friction="1.0" />
  </joint>
  <link name="R_link5">
    <inertial>
      <origin rpy="0 0 0" xyz="0.0651 0.03096 0.00315" />
      <mass value="1.33854" />
      <inertia ixx="0.00146378" ixy="-0.000450624" ixz="0.000284306" iyy="0.00184192" iyz="0.000130866" izz="0.002333524" />
    </inertial>
    <visual>
      <geometry>
        <mesh filename="meshes/link5.stl" />
      </geometry>
      <origin rpy="0 0 0" xyz="0 0 0" />
      <material name="R_White" />
    </visual>
    <collision name="sphere_58">
      <origin xyz="-8.881784197001252e-16 -0.0008895930857889534 0.02095903966676521" rpy="0 0 0" />
      <geometry>
        <sphere radius="0.046" />
      </geometry>
    </collision>
    <collision name="sphere_59">
      <origin xyz="0.07179619208954191 -2.220446049250313e-16 0.00278842089479317" rpy="0 0 0" />
      <geometry>
        <sphere radius="0.051414213562372836" />
      </geometry>
    </collision>
    <collision name="sphere_60">
      <origin xyz="0.07389238809294574 0.06474502320945186 1.6653345369377348e-16" rpy="0 0 0" />
      <geometry>
        <sphere radius="0.05" />
      </geometry>
    </collision>
  </link>
  <joint name="R_joint5" type="revolute">
    <parent link="R_link4" />
    <child link="R_link5" />
    <origin rpy="1.5708 0 0" xyz="0 0 0" />
    <axis xyz="0 0 1" />
    <limit effort="32.0" lower="-1.69297" upper="3.141592653589793" velocity="3.14" />
    <dynamics damping="1.0" friction="1.0" />
  </joint>
  <link name="R_link6">
    <inertial>
      <origin rpy="0 0 0" xyz="0 -0.00677 -0.01098" />
      <mass value="0.17" />
      <inertia ixx="9.3e-05" ixy="-0.0" ixz="-0.0" iyy="5.87e-05" iyz="-3.6e-06" izz="0.000132" />
    </inertial>
    <visual>
      <geometry>
        <mesh filename="meshes/link6.stl" />
      </geometry>
      <origin rpy="0 0 0" xyz="0 0 0" />
      <material name="R_Silver" />
    </visual>
  </link>
  <joint name="R_joint6" type="revolute">
    <parent link="R_link5" />
    <child link="R_link6" />
    <origin rpy="-1.5708 0 0" xyz="0.076 0.097 0" />
    <axis xyz="0 0 1" />
    <limit effort="20.0" lower="-6.283185307179586" upper="6.283185307179586" velocity="3.14" />
    <dynamics damping="1.0" friction="1.0" />
  </joint>
  <transmission name="R_tran1">
    <type>transmission_interface/SimpleTransmission</type>
    <joint name="R_joint1">
      <hardwareInterface>hardware_interface/PositionJointInterface</hardwareInterface>
    </joint>
    <actuator name="R_motor1">
      <hardwareInterface>hardware_interface/PositionJointInterface</hardwareInterface>
      <mechanicalReduction>100</mechanicalReduction>
    </actuator>
  </transmission>
  <transmission name="R_tran2">
    <type>transmission_interface/SimpleTransmission</type>
    <joint name="R_joint2">
      <hardwareInterface>hardware_interface/PositionJointInterface</hardwareInterface>
    </joint>
    <actuator name="R_motor2">
      <hardwareInterface>hardware_interface/PositionJointInterface</hardwareInterface>
      <mechanicalReduction>100</mechanicalReduction>
    </actuator>
  </transmission>
  <transmission name="R_tran3">
    <type>transmission_interface/SimpleTransmission</type>
    <joint name="R_joint3">
      <hardwareInterface>hardware_interface/PositionJointInterface</hardwareInterface>
    </joint>
    <actuator name="R_motor3">
      <hardwareInterface>hardware_interface/PositionJointInterface</hardwareInterface>
      <mechanicalReduction>100</mechanicalReduction>
    </actuator>
  </transmission>
  <transmission name="R_tran4">
    <type>transmission_interface/SimpleTransmission</type>
    <joint name="R_joint4">
      <hardwareInterface>hardware_interface/PositionJointInterface</hardwareInterface>
    </joint>
    <actuator name="R_motor4">
      <hardwareInterface>hardware_interface/PositionJointInterface</hardwareInterface>
      <mechanicalReduction>100</mechanicalReduction>
    </actuator>
  </transmission>
  <transmission name="R_tran5">
    <type>transmission_interface/SimpleTransmission</type>
    <joint name="R_joint5">
      <hardwareInterface>hardware_interface/PositionJointInterface</hardwareInterface>
    </joint>
    <actuator name="R_motor5">
      <hardwareInterface>hardware_interface/PositionJointInterface</hardwareInterface>
      <mechanicalReduction>100</mechanicalReduction>
    </actuator>
  </transmission>
  <transmission name="R_tran6">
    <type>transmission_interface/SimpleTransmission</type>
    <joint name="R_joint6">
      <hardwareInterface>hardware_interface/PositionJointInterface</hardwareInterface>
    </joint>
    <actuator name="R_motor6">
      <hardwareInterface>hardware_interface/PositionJointInterface</hardwareInterface>
      <mechanicalReduction>100</mechanicalReduction>
    </actuator>
  </transmission>
  <gazebo reference="R_link_base">
    <selfCollide>true</selfCollide>
  </gazebo>
  <gazebo reference="R_link1">
    <selfCollide>true</selfCollide>
  </gazebo>
  <gazebo reference="R_link2">
    <selfCollide>true</selfCollide>
  </gazebo>
  <gazebo reference="R_link3">
    <selfCollide>true</selfCollide>
  </gazebo>
  <gazebo reference="R_link4">
    <selfCollide>true</selfCollide>
  </gazebo>
  <gazebo reference="R_link5">
    <selfCollide>true</selfCollide>
  </gazebo>
  <gazebo reference="R_link6">
    <selfCollide>true</selfCollide>
  </gazebo>
  <link name="R_link_eef">
    <visual>
      <geometry>
        <mesh filename="meshes/d435_with_cam_stand.stl" />
      </geometry>
      <origin rpy="0 0 0" xyz="0 0 0" />
      <material name="R_Silver" />
    </visual>
    <collision name="sphere_61">
      <origin xyz="0.06279373469039284 0.023649147603013954 0.015162320295711074" rpy="0 0 0" />
      <geometry>
        <sphere radius="0.02641421356237308" />
      </geometry>
    </collision>
    <collision name="sphere_62">
      <origin xyz="0.061867744815430115 -0.022684149323510372 0.014836797482413067" rpy="0 0 0" />
      <geometry>
        <sphere radius="0.025414213562373177" />
      </geometry>
    </collision>
  </link>
  <link name="R_camera_link" />
  <link name="R_camera_depth_frame" />
  <link name="R_camera_depth_optical_frame" />
  <link name="R_camera_color_frame" />
  <link name="R_camera_color_optical_frame" />
  <link name="R_camera_left_ir_frame" />
  <link name="R_camera_left_ir_optical_frame" />
  <link name="R_camera_right_ir_frame" />
  <link name="R_camera_right_ir_optical_frame" />
  <joint name="R_camera_link_joint" type="fixed">
    <parent link="R_link_eef" />
    <child link="R_camera_link" />
    <origin rpy="3.141592653589793 -1.5707963267948966 0" xyz="0.06746 -0.0175 0.0237" />
  </joint>
  <joint name="R_camera_depth_joint" type="fixed">
    <parent link="R_camera_link" />
    <child link="R_camera_depth_frame" />
    <origin rpy="0 0 0" xyz="0 0 0" />
  </joint>
  <joint name="R_camera_depth_optical_joint" type="fixed">
    <parent link="R_camera_depth_frame" />
    <child link="R_camera_depth_optical_frame" />
    <origin rpy="-1.5707963267948966 0 -1.5707963267948966" xyz="0 0 0" />
  </joint>
  <joint name="R_camera_color_joint" type="fixed">
    <parent link="R_camera_link" />
    <child link="R_camera_color_frame" />
    <origin rpy="0 0 0" xyz="0 0.015 0" />
  </joint>
  <joint name="R_camera_color_optical_joint" type="fixed">
    <parent link="R_camera_color_frame" />
    <child link="R_camera_color_optical_frame" />
    <origin rpy="-1.5707963267948966 0 -1.5707963267948966" xyz="0 0 0" />
  </joint>
  <joint name="R_camera_left_ir_joint" type="fixed">
    <parent link="R_camera_link" />
    <child link="R_camera_left_ir_frame" />
    <origin rpy="0 0 0" xyz="0 0 0" />
  </joint>
  <joint name="R_camera_left_ir_optical_joint" type="fixed">
    <parent link="R_camera_left_ir_frame" />
    <child link="R_camera_left_ir_optical_frame" />
    <origin rpy="-1.5707963267948966 0 -1.5707963267948966" xyz="0 0 0" />
  </joint>
  <joint name="R_camera_right_ir_joint" type="fixed">
    <parent link="R_camera_link" />
    <child link="R_camera_right_ir_frame" />
    <origin rpy="0 0 0" xyz="0 -0.050 0" />
  </joint>
  <joint name="R_camera_right_ir_optical_joint" type="fixed">
    <parent link="R_camera_right_ir_frame" />
    <child link="R_camera_right_ir_optical_frame" />
    <origin rpy="-1.5707963267948966 0 -1.5707963267948966" xyz="0 0 0" />
  </joint>
  <gazebo reference="R_camera_depth_frame">
    <sensor name="R_cameradepth" type="depth">
      <camera name="R_camera">
        <horizontal_fov>1.57</horizontal_fov>
        <image>
          <width>1280</width>
          <height>720</height>
        </image>
        <clip>
          <near>0.1</near>
          <far>100</far>
        </clip>
        <noise>
          <type>gaussian</type>
          <mean>0.0</mean>
          <stddev>0.100</stddev>
        </noise>
      </camera>
      <always_on>1</always_on>
      <update_rate>30</update_rate>
      <visualize>0</visualize>
    </sensor>
  </gazebo>
  <gazebo reference="R_camera_color_frame">
    <sensor name="R_cameracolor" type="camera">
      <camera name="R_camera">
        <horizontal_fov>1.57</horizontal_fov>
        <image>
          <width>1280</width>
          <height>720</height>
          <format>RGB_INT8</format>
        </image>
        <clip>
          <near>0.1</near>
          <far>100</far>
        </clip>
        <noise>
          <type>gaussian</type>
          <mean>0.0</mean>
          <stddev>0.007</stddev>
        </noise>
      </camera>
      <always_on>1</always_on>
      <update_rate>30</update_rate>
      <visualize>1</visualize>
    </sensor>
  </gazebo>
  <gazebo reference="R_camera_left_ir_frame">
    <sensor name="R_cameraired1" type="camera">
      <camera name="R_camera">
        <horizontal_fov>1.57</horizontal_fov>
        <image>
          <width>1280</width>
          <height>720</height>
          <format>L_INT8</format>
        </image>
        <clip>
          <near>0.1</near>
          <far>100</far>
        </clip>
        <noise>
          <type>gaussian</type>
          <mean>0.0</mean>
          <stddev>0.05</stddev>
        </noise>
      </camera>
      <always_on>1</always_on>
      <update_rate>30</update_rate>
      <visualize>0</visualize>
    </sensor>
  </gazebo>
  <gazebo reference="R_camera_right_ir_frame">
    <sensor name="R_cameraired2" type="camera">
      <camera name="R_camera">
        <horizontal_fov>1.57</horizontal_fov>
        <image>
          <width>1280</width>
          <height>720</height>
          <format>L_INT8</format>
        </image>
        <clip>
          <near>0.1</near>
          <far>100</far>
        </clip>
        <noise>
          <type>gaussian</type>
          <mean>0.0</mean>
          <stddev>0.05</stddev>
        </noise>
      </camera>
      <always_on>1</always_on>
      <update_rate>30</update_rate>
      <visualize>0</visualize>
    </sensor>
  </gazebo>
  <gazebo>
    <plugin filename="librealsense_gazebo_plugin.so" name="realsense_gazebo_camera">
      <prefix>R_camera</prefix>
      <depthUpdateRate>30.0</depthUpdateRate>
      <colorUpdateRate>30.0</colorUpdateRate>
      <infraredUpdateRate>30.0</infraredUpdateRate>
      <depthTopicName>R_aligned_depth_to_color/image_raw</depthTopicName>
      <depthCameraInfoTopicName>R_depth/camera_info</depthCameraInfoTopicName>
      <colorTopicName>R_color/image_raw</colorTopicName>
      <colorCameraInfoTopicName>R_color/camera_info</colorCameraInfoTopicName>
      <infrared1TopicName>R_infra1/image_raw</infrared1TopicName>
      <infrared1CameraInfoTopicName>R_infra1/camera_info</infrared1CameraInfoTopicName>
      <infrared2TopicName>R_infra2/image_raw</infrared2TopicName>
      <infrared2CameraInfoTopicName>R_infra2/camera_info</infrared2CameraInfoTopicName>
      <colorOpticalframeName>R_camera_color_optical_frame</colorOpticalframeName>
      <depthOpticalframeName>R_camera_depth_optical_frame</depthOpticalframeName>
      <infrared1OpticalframeName>R_camera_left_ir_optical_frame</infrared1OpticalframeName>
      <infrared2OpticalframeName>R_camera_right_ir_optical_frame</infrared2OpticalframeName>
      <rangeMinDepth>0.3</rangeMinDepth>
      <rangeMaxDepth>3.0</rangeMaxDepth>
      <pointCloud>true</pointCloud>
      <pointCloudTopicName>R_depth/color/points</pointCloudTopicName>
      <pointCloudCutoff>0.3</pointCloudCutoff>
    </plugin>
  </gazebo>
  <joint name="R_joint_eef" type="fixed">
    <origin rpy="0 0 0" xyz="0 0 0" />
    <parent link="R_link6" />
    <child link="R_link_eef" />
  </joint>
  <joint name="R_gripper_fix" type="fixed">
    <parent link="R_link_eef" />
    <child link="R_xarm_gripper_base_link" />
    <origin rpy="0 0 0" xyz="0 0 0" />
  </joint>
  <link name="R_xarm_gripper_base_link">
    <inertial>
      <origin rpy="0 0 0" xyz="-0.00065489 -0.0018497 0.048028" />
      <mass value="0.54156" />
      <inertia ixx="0.00047106" ixy="3.9292E-07" ixz="2.6537E-06" iyy="0.00033072" iyz="-1.0975E-05" izz="0.00025642" />
    </inertial>
    <visual>
      <geometry>
        <mesh filename="meshes/base_link.stl" />
      </geometry>
      <origin rpy="0 0 0" xyz="0 0 0" />
      <material name="R_White" />
    </visual>
    <collision name="sphere_63">
      <origin xyz="0.0 0.021408598442209437 0.038569046798902606" rpy="0 0 0" />
      <geometry>
        <sphere radius="0.045" />
      </geometry>
    </collision>
    <collision name="sphere_64">
      <origin xyz="0.0 -0.027208259023810577 0.02974245065168324" rpy="0 0 0" />
      <geometry>
        <sphere radius="0.045" />
      </geometry>
    </collision>
    <collision name="sphere_65">
      <origin xyz="-1.1102230246251565e-16 0.0444656172722705 0.08318401484654281" rpy="0 0 0" />
      <geometry>
        <sphere radius="0.044" />
      </geometry>
    </collision>
    <collision name="sphere_66">
      <origin xyz="-1.1102230246251565e-16 -0.05169408008738835 0.08041762764194593" rpy="0 0 0" />
      <geometry>
        <sphere radius="0.044" />
      </geometry>
    </collision>
    <collision name="sphere_67">
      <origin xyz="-1.1102230246251565e-16 -1.6653345369377348e-16 0.06765859485327008" rpy="0 0 0" />
      <geometry>
        <sphere radius="0.044" />
      </geometry>
    </collision>
  </link>
  <link name="R_left_outer_knuckle">
    <inertial>
      <origin rpy="0 0 0" xyz="2.9948E-14 0.021559 0.015181" />
      <mass value="0.033618" />
      <inertia ixx="1.9111E-05" ixy="-1.8803E-17" ixz="-1.1002E-17" iyy="6.6256E-06" iyz="-7.3008E-06" izz="1.3185E-05" />
    </inertial>
    <visual>
      <geometry>
        <mesh filename="meshes/left_outer_knuckle.stl" />
      </geometry>
      <origin rpy="0 0 0" xyz="0 0 0" />
      <material name="R_Silver" />
    </visual>
  </link>
  <joint name="R_drive_joint" type="revolute">
    <origin rpy="0 0 0" xyz="0 0.035 0.059098" />
    <parent link="R_xarm_gripper_base_link" />
    <child link="R_left_outer_knuckle" />
    <axis xyz="1 0 0" />
    <limit effort="50" lower="0" upper="0.85" velocity="2" />
  </joint>
  <link name="R_left_finger">
    <inertial>
      <origin rpy="0 0 0" xyz="-2.4536E-14 -0.016413 0.029258" />
      <mass value="0.048304" />
      <inertia ixx="1.7493E-05" ixy="-4.2156E-19" ixz="6.9164E-18" iyy="1.7225E-05" iyz="4.6433E-06" izz="5.1466E-06" />
    </inertial>
    <visual>
      <geometry>
        <mesh filename="meshes/left_finger.stl" />
      </geometry>
      <origin rpy="0 0 0" xyz="0 0 0" />
      <material name="R_Silver" />
    </visual>
    <collision name="sphere_68">
      <origin xyz="-1.2212453270876722e-15 -0.015735800096064345 0.048885242158388076" rpy="0 0 0" />
      <geometry>
        <sphere radius="0.019" />
      </geometry>
    </collision>
    <collision name="sphere_69">
      <origin xyz="0.0 -0.015374925454853472 0.03324483777039544" rpy="0 0 0" />
      <geometry>
        <sphere radius="0.019" />
      </geometry>
    </collision>
  </link>
  <joint name="R_left_finger_joint" type="revolute">
    <origin rpy="0 0 0" xyz="0 0.035465 0.042039" />
    <parent link="R_left_outer_knuckle" />
    <child link="R_left_finger" />
    <axis xyz="-1 0 0" />
    <limit effort="50" lower="0" upper="0.85" velocity="2" />
    <mimic joint="R_drive_joint" multiplier="1" offset="0" />
  </joint>
  <link name="R_left_inner_knuckle">
    <inertial>
      <origin rpy="0 0 0" xyz="1.86600784687907E-06 0.0220467847633621 0.0261334672830885" />
      <mass value="0.0230125781256706" />
      <inertia ixx="6.09490024271906E-06" ixy="6.06651326160071E-11" ixz="7.19102670500635E-11" iyy="6.01955084375188E-06" iyz="-2.75316812991721E-06" izz="5.07862004479903E-06" />
    </inertial>
    <visual>
      <geometry>
        <mesh filename="meshes/left_inner_knuckle.stl" />
      </geometry>
      <origin rpy="0 0 0" xyz="0 0 0" />
      <material name="R_Silver" />
    </visual>
  </link>
  <joint name="R_left_inner_knuckle_joint" type="revolute">
    <origin rpy="0 0 0" xyz="0 0.02 0.074098" />
    <parent link="R_xarm_gripper_base_link" />
    <child link="R_left_inner_knuckle" />
    <axis xyz="1 0 0" />
    <limit effort="50" lower="0" upper="0.85" velocity="2" />
    <mimic joint="R_drive_joint" multiplier="1" offset="0" />
  </joint>
  <link name="R_right_outer_knuckle">
    <inertial>
      <origin rpy="0 0 0" xyz="-3.1669E-14 -0.021559 0.015181" />
      <mass value="0.033618" />
      <inertia ixx="1.9111E-05" ixy="-1.8789E-17" ixz="1.0986E-17" iyy="6.6256E-06" iyz="7.3008E-06" izz="1.3185E-05" />
    </inertial>
    <visual>
      <geometry>
        <mesh filename="meshes/right_outer_knuckle.stl" />
      </geometry>
      <origin rpy="0 0 0" xyz="0 0 0" />
      <material name="R_Silver" />
    </visual>
  </link>
  <joint name="R_right_outer_knuckle_joint" type="revolute">
    <origin rpy="0 0 0" xyz="0 -0.035 0.059098" />
    <parent link="R_xarm_gripper_base_link" />
    <child link="R_right_outer_knuckle" />
    <axis xyz="-1 0 0" />
    <limit effort="50" lower="0" upper="0.85" velocity="2" />
    <mimic joint="R_drive_joint" multiplier="1" offset="0" />
  </joint>
  <link name="R_right_finger">
    <inertial>
      <origin rpy="0 0 0" xyz="2.5618E-14 0.016413 0.029258" />
      <mass value="0.048304" />
      <inertia ixx="1.7493E-05" ixy="-5.0014E-19" ixz="-7.5079E-18" iyy="1.7225E-05" iyz="-4.6435E-06" izz="5.1466E-06" />
    </inertial>
    <visual>
      <geometry>
        <mesh filename="meshes/right_finger.stl" />
      </geometry>
      <origin rpy="0 0 0" xyz="0 0 0" />
      <material name="R_Silver" />
    </visual>
    <collision name="sphere_70">
      <origin xyz="-4.440892098500626e-16 0.013904890286745408 0.04785105103424969" rpy="0 0 0" />
      <geometry>
        <sphere radius="0.019" />
      </geometry>
    </collision>
    <collision name="sphere_71">
      <origin xyz="-3.3306690738754696e-16 0.013608832539368731 0.0326232671765182" rpy="0 0 0" />
      <geometry>
        <sphere radius="0.019" />
      </geometry>
    </collision>
  </link>
  <joint name="R_right_finger_joint" type="revolute">
    <origin rpy="0 0 0" xyz="0 -0.035465 0.042039" />
    <parent link="R_right_outer_knuckle" />
    <child link="R_right_finger" />
    <axis xyz="1 0 0" />
    <limit effort="50" lower="0" upper="0.85" velocity="2" />
    <mimic joint="R_drive_joint" multiplier="1" offset="0" />
  </joint>
  <link name="R_right_inner_knuckle">
    <inertial>
      <origin rpy="0 0 0" xyz="1.866E-06 -0.022047 0.026133" />
      <mass value="0.023013" />
      <inertia ixx="6.0949E-06" ixy="-6.0665E-11" ixz="7.191E-11" iyy="6.0197E-06" iyz="2.7531E-06" izz="5.0784E-06" />
    </inertial>
    <visual>
      <geometry>
        <mesh filename="meshes/right_inner_knuckle.stl" />
      </geometry>
      <origin rpy="0 0 0" xyz="0 0 0" />
      <material name="R_Silver" />
    </visual>
  </link>
  <joint name="R_right_inner_knuckle_joint" type="revolute">
    <origin rpy="0 0 0" xyz="0 -0.02 0.074098" />
    <parent link="R_xarm_gripper_base_link" />
    <child link="R_right_inner_knuckle" />
    <axis xyz="-1 0 0" />
    <limit effort="50" lower="0" upper="0.85" velocity="2" />
    <mimic joint="R_drive_joint" multiplier="1" offset="0" />
  </joint>
  <link name="R_link_tcp" />
  <joint name="R_joint_tcp" type="fixed">
    <origin rpy="0 0 0" xyz="0 0 0.172" />
    <parent link="R_xarm_gripper_base_link" />
    <child link="R_link_tcp" />
  </joint>
  <transmission name="R_drive_joint_trans">
    <type>transmission_interface/SimpleTransmission</type>
    <joint name="R_drive_joint">
      <hardwareInterface>hardware_interface/PositionJointInterface</hardwareInterface>
    </joint>
    <actuator name="R_drive_joint_motor">
      <hardwareInterface>hardware_interface/PositionJointInterface</hardwareInterface>
      <mechanicalReduction>1</mechanicalReduction>
    </actuator>
  </transmission>
  <gazebo reference="R_xarm_gripper_base_link">
    <selfCollide>false</selfCollide>
  </gazebo>
  <gazebo reference="R_left_outer_knuckle">
    <selfCollide>false</selfCollide>
  </gazebo>
  <gazebo reference="R_left_finger">
    <selfCollide>false</selfCollide>
  </gazebo>
  <gazebo reference="R_left_inner_knuckle">
    <selfCollide>false</selfCollide>
  </gazebo>
  <gazebo reference="R_right_outer_knuckle">
    <selfCollide>false</selfCollide>
  </gazebo>
  <gazebo reference="R_right_finger">
    <selfCollide>false</selfCollide>
  </gazebo>
  <gazebo reference="R_right_inner_knuckle">
    <selfCollide>false</selfCollide>
  </gazebo>
  <gazebo>
    <plugin filename="libgazebo_grasp_fix.so" name="gazebo_grasp_fix">
      <arm>
        <arm_name>xarm_gripper</arm_name>
        <palm_link>R_link6</palm_link>
        <gripper_link>R_left_inner_knuckle</gripper_link>
        <gripper_link>R_right_inner_knuckle</gripper_link>
        <gripper_link>R_left_finger</gripper_link>
        <gripper_link>R_right_finger</gripper_link>
      </arm>
      <forces_angle_tolerance>100</forces_angle_tolerance>
      <update_rate>10</update_rate>
      <grip_count_threshold>2</grip_count_threshold>
      <max_grip_count>3</max_grip_count>
      <release_tolerance>0.0198</release_tolerance>
      <disable_collisions_on_attach>false</disable_collisions_on_attach>
      <contact_topic>__default_topic__</contact_topic>
    </plugin>
  </gazebo>
  <gazebo>
    <plugin filename="libroboticsgroup_gazebo_mimic_joint_plugin.so" name="R_left_finger_jointmimic_joint_plugin">
      <joint>R_drive_joint</joint>
      <mimicJoint>R_left_finger_joint</mimicJoint>
      <multiplier>1.0</multiplier>
      <offset>0</offset>
      <sensitiveness>0.0</sensitiveness>
      <maxEffort>10.0</maxEffort>
    </plugin>
  </gazebo>
  <gazebo>
    <plugin filename="libroboticsgroup_gazebo_mimic_joint_plugin.so" name="R_left_inner_knuckle_jointmimic_joint_plugin">
      <joint>R_drive_joint</joint>
      <mimicJoint>R_left_inner_knuckle_joint</mimicJoint>
      <multiplier>1.0</multiplier>
      <offset>0</offset>
      <sensitiveness>0.0</sensitiveness>
      <maxEffort>10.0</maxEffort>
    </plugin>
  </gazebo>
  <gazebo>
    <plugin filename="libroboticsgroup_gazebo_mimic_joint_plugin.so" name="R_right_outer_knuckle_jointmimic_joint_plugin">
      <joint>R_drive_joint</joint>
      <mimicJoint>R_right_outer_knuckle_joint</mimicJoint>
      <multiplier>1.0</multiplier>
      <offset>0</offset>
      <sensitiveness>0.0</sensitiveness>
      <maxEffort>10.0</maxEffort>
    </plugin>
  </gazebo>
  <gazebo>
    <plugin filename="libroboticsgroup_gazebo_mimic_joint_plugin.so" name="R_right_finger_jointmimic_joint_plugin">
      <joint>R_drive_joint</joint>
      <mimicJoint>R_right_finger_joint</mimicJoint>
      <multiplier>1.0</multiplier>
      <offset>0</offset>
      <sensitiveness>0.0</sensitiveness>
      <maxEffort>10.0</maxEffort>
    </plugin>
  </gazebo>
  <gazebo>
    <plugin filename="libroboticsgroup_gazebo_mimic_joint_plugin.so" name="R_right_inner_knuckle_jointmimic_joint_plugin">
      <joint>R_drive_joint</joint>
      <mimicJoint>R_right_inner_knuckle_joint</mimicJoint>
      <multiplier>1.0</multiplier>
      <offset>0</offset>
      <sensitiveness>0.0</sensitiveness>
      <maxEffort>10.0</maxEffort>
    </plugin>
  </gazebo>
  <link name="R_camera_calib_link" />
  <joint name="R_camera_calib_mount" type="fixed">
    <parent link="R_link6" />
    <child link="R_camera_calib_link" />
    <origin rpy="-0.004565 -0.002717 -1.549195" xyz="0.030576 0.068701 -0.016253" />
  </joint>
</robot>
